Workbook

Sheet サマリー
A1: Bsharp 財務モデル — サマリー
A2: 全て自動計算（緑字 = 他シート参照）。感度分析は「前提」シートを編集
A3: 指標 | B3: 値 | C3: 備考
A4: M12 月商 | B4: =PL!M17 | C4: ゴール: ¥300,000
A5: M12 営業利益 | B5: =PL!M31
A6: 月次黒字化 | B6: =MATCH(TRUE,INDEX(PL!B31:S31>0,0),0) | C6: 営業利益が初めて黒字になる月
A7: 損益分岐 注文数/月 | B7: =(前提!$B$48+前提!$B$14)/前提!$B$47 | C7: 広告込み固定費 ÷ 貢献利益/注文
A8: 必要自己資金（資金の谷） | B8: =-MIN(CF!B23:T23) | C8: 累計CFの最大マイナス幅
A9: 資金の谷の月 | B9: =MATCH(MIN(CF!B23:T23),CF!B23:T23,0)-1 | C9: M0起点
A10: 投資回収（累計CF黒字化） | B10: =IFERROR(MATCH(TRUE,INDEX(CF!C23:T23>=0,0),0),"18ヶ月超")
A11: 18ヶ月 累計営業利益 | B11: =PL!S32
A12: 貢献利益/注文 | B12: =前提!$B$47 | C12: 前提シートの計算値
A14: 使い方: 「前提」シートの青字セルを変えると全シートが再計算される。
A15: シナリオ係数 0.6 / 1.0 / 1.4 で保守 / 標準 / 強気を切替。
A16: 構造の変更（行追加・ロジック変更）は docs/finance/build_financial_model.py を編集して再生成する。

Sheet 前提
A1: Bsharp 財務モデル
A2: 前提条件・入力パラメータ（青字 = 可変入力セル / 黒 = 自動計算）
A3: パラメータ | B3: 値 | C3: 備考
A4: 売上サイド
A5: シナリオ係数（セッションに乗算） | B5: 1 | C5: 保守0.6 / 標準1.0 / 強気1.4
A6: セッション数 初月(M1) | B6: 400 | C6: 知人・コミュニティ告知込み
A7: セッション数 月次増分 | B7: 320 | C7: 週3〜4本のリール/ショート+月2〜4本ブログ前提
A8: CVRベース（オーガニック） | B8: 0.012 | C8: EC相場1%への上振れ仮説
A9: CVR月次改善（M4以降/月） | B9: 0.00011 | C9: レビュー・実績蓄積効果。M12で約1.3%
A10: 知人ブースト注文 M1 | B10: 6 | C10: 開店告知の初期注文
A11: 知人ブースト注文 M2 | B11: 3
A12: 月次リピート率 | B12: 0.03 | C12: 累計購入者に対する月次再購入率
A13: 広告開始月 | B13: 3 | C13: オーディエンス1,000人ゲート。目安M3
A14: 広告費/月（Meta・リタゲ中心） | B14: 10000 | C14: 確定方針
A15: リタゲCPC | B15: 60 | C15: 相場仮説
A16: リタゲCVR | B16: 0.03 | C16: 相場仮説
A17: コストサイド
A18: 仕入掛率 | B18: 0.6 | C18: 全件交渉未確定。最重要感度変数
A19: 決済手数料率 | B19: 0.0355 | C19: Shopify Payments Basic 国内カード（確定）
A20: 破損・不良率（商品売上比） | B20: 0.015 | C20: 再送コスト込みの引当
A21: 顧客負担送料（未到達時・全国一律） | B21: 880 | C21: 設計値
A22: 送料無料ライン | B22: 11000 | C22: 高ライン=送料収入最大化。到達率≈0%。詳細は02
A23: 仕入送料/発注回 | B23: 2000 | C23: 仕入れ先条件で置換
A24: 固定費（月次）
A25: Shopify Basic（年払い月割） | B25: 3650 | C25: 現金は年1回¥43,800
A26: 独自ドメイン（月割） | B26: 170 | C26: 現金は年1回¥2,000
A27: 撮影ランニング | B27: 5000 | C27: スタジオ2〜3回/年+撮影消耗品の月割
A28: 初期投資・CF設定
A29: 初期仕入（原価） | B29: 440000 | C29: 縮小・回転型: 主力10SKU×10個+他20SKU×5〜6個
A30: 撮影初期（キービジュアル・備品） | B30: 75000
A31: 梱包資材 初期ロット | B31: 40000 | C31: 月次資材費はこの在庫を消化後に現金化
A32: 開業その他 | B32: 10000 | C32: 名刺・印鑑等
A33: Shopify 年払い額 | B33: 43800 | C33: M0とM12に支払
A34: ドメイン 年額 | B34: 2000 | C34: M0とM12に支払
A35: 在庫カバー月数（発注基準） | B35: 2 | C35: 期末在庫≥翌月原価×この月数となるよう発注
A36: 注文構成（送料無料ライン到達は自動判定）
A37: バケット | B37: 構成比 | C37: 注文額 | D37: 送料実費 | E37: 資材費 | F37: 到達フラグ
A38: 1点買い（60〜80サイズ） | B38: 0.5 | C38: 3000 | D38: 870 | E38: 250 | F38: =IF(C38>=B22,1,0)
A39: 2点買い（80サイズ） | B39: 0.27 | C39: 5800 | D39: 1082 | E39: 320 | F39: =IF(C39>=B22,1,0)
A40: 3点以上（80〜100サイズ） | B40: 0.23 | C40: 8800 | D40: 1183 | E40: 420 | F40: =IF(C40>=B22,1,0)
...

Sheet PL
A1: 月次PL（M1〜M18）
B2: M1 | C2: M2 | D2: M3 | E2: M4 | F2: M5 | G2: M6 | H2: M7 | I2: M8 | J2: M9 | K2: M10 | L2: M11 | M2: M12 | N2: M13 | O2: M14 | P2: M15 | Q2: M16 | R2: M17 | S2: M18
A3: 集客・注文
A4: セッション数 | B4: =ROUND((前提!$B$6+前提!$B$7*0)*前提!$B$5,0) | C4: =ROUND((前提!$B$6+前提!$B$7*1)*前提!$B$5,0) | D4: =ROUND((前提!$B$6+前提!$B$7*2)*前提!$B$5,0) | E4: =ROUND((前提!$B$6+前提!$B$7*3)*前提!$B$5,0) | F4: =ROUND((前提!$B$6+前提!$B$7*4)*前提!$B$5,0) | G4: =ROUND((前提!$B$6+前提!$B$7*5)*前提!$B$5,0) | H4: =ROUND((前提!$B$6+前提!$B$7*6)*前提!$B$5,0) | I4: =ROUND((前提!$B$6+前提!$B$7*7)*前提!$B$5,0) | J4: =ROUND((前提!$B$6+前提!$B$7*8)*前提!$B$5,0) | K4: =ROUND((前提!$B$6+前提!$B$7*9)*前提!$B$5,0) | L4: =ROUND((前提!$B$6+前提!$B$7*10)*前提!$B$5,0) | M4: =ROUND((前提!$B$6+前提!$B$7*11)*前提!$B$5,0) | N4: =ROUND((前提!$B$6+前提!$B$7*12)*前提!$B$5,0) | O4: =ROUND((前提!$B$6+前提!$B$7*13)*前提!$B$5,0) | P4: =ROUND((前提!$B$6+前提!$B$7*14)*前提!$B$5,0) | Q4: =ROUND((前提!$B$6+前提!$B$7*15)*前提!$B$5,0) | R4: =ROUND((前提!$B$6+前提!$B$7*16)*前提!$B$5,0) | S4: =ROUND((前提!$B$6+前提!$B$7*17)*前提!$B$5,0)
A5: CVR | B5: =前提!$B$8+前提!$B$9*0 | C5: =前提!$B$8+前提!$B$9*0 | D5: =前提!$B$8+前提!$B$9*0 | E5: =前提!$B$8+前提!$B$9*1 | F5: =前提!$B$8+前提!$B$9*2 | G5: =前提!$B$8+前提!$B$9*3 | H5: =前提!$B$8+前提!$B$9*4 | I5: =前提!$B$8+前提!$B$9*5 | J5: =前提!$B$8+前提!$B$9*6 | K5: =前提!$B$8+前提!$B$9*7 | L5: =前提!$B$8+前提!$B$9*8 | M5: =前提!$B$8+前提!$B$9*9 | N5: =前提!$B$8+前提!$B$9*10 | O5: =前提!$B$8+前提!$B$9*11 | P5: =前提!$B$8+前提!$B$9*12 | Q5: =前提!$B$8+前提!$B$9*13 | R5: =前提!$B$8+前提!$B$9*14 | S5: =前提!$B$8+前提!$B$9*15
A6: オーガニック新規注文 | B6: =B4*B5 | C6: =C4*C5 | D6: =D4*D5 | E6: =E4*E5 | F6: =F4*F5 | G6: =G4*G5 | H6: =H4*H5 | I6: =I4*I5 | ... S6: =S4*S5
A7: 知人ブースト注文 | B7: =前提!$B$10 | C7: =前提!$B$11 | D7: =0 | E7: =0 | F7: =0 | G7: =0 | H7: =0 | I7: =0 | J7: =0 | K7: =0 | ... S7: =0
A8: リタゲ注文 | B8: =IF(1>=前提!$B$13,前提!$B$14/前提!$B$15*前提!$B$16,0) | C8: =IF(2>=前提!$B$13,前提!$B$14/前提!$B$15*前提!$B$16,0) | D8: =IF(3>=前提!$B$13,前提!$B$14/前提!$B$15*前提!$B$16,0) | E8: =IF(4>=前提!$B$13,前提!$B$14/前提!$B$15*前提!$B$16,0) | F8: =IF(5>=前提!$B$13,前提!$B$14/前提!$B$15*前提!$B$16,0) | G8: =IF(6>=前提!$B$13,前提!$B$14/前提!$B$15*前提!$B$16,0) | H8: =IF(7>=前提!$B$13,前提!$B$14/前提!$B$15*前提!$B$16,0) | I8: =IF(8>=前提!$B$13,前提!$B$14/前提!$B$15*前提!$B$16,0) | J8: =IF(9>=前提!$B$13,前提!$B$14/前提!$B$15*前提!$B$16,0) | K8: =IF(10>=前提!$B$13,前提!$B$14/前提!$B$15*前提!$B$16,0) | L8: =IF(11>=前提!$B$13,前提!$B$14/前提!$B$15*前提!$B$16,0) | M8: =IF(12>=前提!$B$13,前提!$B$14/前提!$B$15*前提!$B$16,0) | N8: =IF(13>=前提!$B$13,前提!$B$14/前提!$B$15*前提!$B$16,0) | O8: =IF(14>=前提!$B$13,前提!$B$14/前提!$B$15*前提!$B$16,0) | P8: =IF(15>=前提!$B$13,前提!$B$14/前提!$B$15*前提!$B$16,0) | Q8: =IF(16>=前提!$B$13,前提!$B$14/前提!$B$15*前提!$B$16,0) | R8: =IF(17>=前提!$B$13,前提!$B$14/前提!$B$15*前提!$B$16,0) | S8: =IF(18>=前提!$B$13,前提!$B$14/前提!$B$15*前提!$B$16,0)
A9: 新規注文 計 | B9: =SUM(B6:B8) | C9: =SUM(C6:C8) | D9: =SUM(D6:D8) | E9: =SUM(E6:E8) | F9: =SUM(F6:F8) | G9: =SUM(G6:G8) | H9: =SUM(H6:H8) | I9: =SUM(I6:I8) | ... S9: =SUM(S6:S8)
A10: 累計購入者数 | B10: =B9 | C10: =B10+C9 | D10: =C10+D9 | E10: =D10+E9 | F10: =E10+F9 | G10: =F10+G9 | H10: =G10+H9 | I10: =H10+I9 | J10: =I10+J9 | ... S10: =R10+S9
A11: リピート注文 | B11: =0 | C11: =B10*前提!$B$12 | D11: =C10*前提!$B$12 | E11: =D10*前提!$B$12 | F11: =E10*前提!$B$12 | G11: =F10*前提!$B$12 | H11: =G10*前提!$B$12 | I11: =H10*前提!$B$12 | J11: =I10*前提!$B$12 | ... S11: =R10*前提!$B$12
A12: 総注文数 | B12: =B9+B11 | C12: =C9+C11 | D12: =D9+D11 | E12: =E9+E11 | F12: =F9+F11 | G12: =G9+G11 | H12: =H9+H11 | I12: =I9+I11 | ... S12: =S9+S11
A13: 売上
A14: AOV | B14: =前提!$B$42 | C14: =前提!$B$42 | D14: =前提!$B$42 | E14: =前提!$B$42 | F14: =前提!$B$42 | G14: =前提!$B$42 | H14: =前提!$B$42 | I14: =前提!$B$42 | ... S14: =前提!$B$42
A15: 商品売上 | B15: =B12*B14 | C15: =C12*C14 | D15: =D12*D14 | E15: =E12*E14 | F15: =F12*F14 | G15: =G12*G14 | H15: =H12*H14 | I15: =I12*I14 | ... S15: =S12*S14
A16: 送料収入 | B16: =B12*前提!$B$43 | C16: =C12*前提!$B$43 | D16: =D12*前提!$B$43 | E16: =E12*前提!$B$43 | F16: =F12*前提!$B$43 | G16: =G12*前提!$B$43 | H16: =H12*前提!$B$43 | I16: =I12*前提!$B$43 | ... S16: =S12*前提!$B$43
A17: 売上高 合計 | B17: =B15+B16 | C17: =C15+C16 | D17: =D15+D16 | E17: =E15+E16 | F17: =F15+F16 | G17: =G15+G16 | H17: =H15+H16 | I17: =I15+I16 | ... S17: =S15+S16
A18: 変動費
A19: 売上原価 | B19: =B15*前提!$B$18 | C19: =C15*前提!$B$18 | D19: =D15*前提!$B$18 | E19: =E15*前提!$B$18 | F19: =F15*前提!$B$18 | G19: =G15*前提!$B$18 | H19: =H15*前提!$B$18 | I19: =I15*前提!$B$18 | ... S19: =S15*前提!$B$18
A20: 売上総利益 | B20: =B17-B19 | C20: =C17-C19 | D20: =D17-D19 | E20: =E17-E19 | F20: =F17-F19 | G20: =G17-G19 | H20: =H17-H19 | I20: =I17-I19 | ... S20: =S17-S19
A21: 決済手数料 | B21: =B17*前提!$B$19 | C21: =C17*前提!$B$19 | D21: =D17*前提!$B$19 | E21: =E17*前提!$B$19 | F21: =F17*前提!$B$19 | G21: =G17*前提!$B$19 | H21: =H17*前提!$B$19 | I21: =I17*前提!$B$19 | ... S21: =S17*前提!$B$19
A22: 発送送料 | B22: =B12*前提!$B$44 | C22: =C12*前提!$B$44 | D22: =D12*前提!$B$44 | E22: =E12*前提!$B$44 | F22: =F12*前提!$B$44 | G22: =G12*前提!$B$44 | H22: =H12*前提!$B$44 | I22: =I12*前提!$B$44 | ... S22: =S12*前提!$B$44
A23: 梱包資材費 | B23: =B12*前提!$B$45 | C23: =C12*前提!$B$45 | D23: =D12*前提!$B$45 | E23: =E12*前提!$B$45 | F23: =F12*前提!$B$45 | G23: =G12*前提!$B$45 | H23: =H12*前提!$B$45 | I23: =I12*前提!$B$45 | ... S23: =S12*前提!$B$45
A24: 破損・不良 | B24: =B15*前提!$B$20 | C24: =C15*前提!$B$20 | D24: =D15*前提!$B$20 | E24: =E15*前提!$B$20 | F24: =F15*前提!$B$20 | G24: =G15*前提!$B$20 | H24: =H15*前提!$B$20 | I24: =I15*前提!$B$20 | ... S24: =S15*前提!$B$20
A25: 仕入送料 | B25: =CF!C12 | C25: =CF!D12 | D25: =CF!E12 | E25: =CF!F12 | F25: =CF!G12 | G25: =CF!H12 | H25: =CF!I12 | I25: =CF!J12 | ... S25: =CF!T12
A26: 利益
A27: 貢献利益 | B27: =B20-B21-B22-B23-B24-B25 | C27: =C20-C21-C22-C23-C24-C25 | D27: =D20-D21-D22-D23-D24-D25 | E27: =E20-E21-E22-E23-E24-E25 | F27: =F20-F21-F22-F23-F24-F25 | G27: =G20-G21-G22-G23-G24-G25 | H27: =H20-H21-H22-H23-H24-H25 | I27: =I20-I21-I22-I23-I24-I25 | ... S27: =S20-S21-S22-S23-S24-S25
A28: 貢献利益率 | B28: =IF(B17=0,0,B27/B17) | C28: =IF(C17=0,0,C27/C17) | D28: =IF(D17=0,0,D27/D17) | E28: =IF(E17=0,0,E27/E17) | F28: =IF(F17=0,0,F27/F17) | G28: =IF(G17=0,0,G27/G17) | H28: =IF(H17=0,0,H27/H17) | I28: =IF(I17=0,0,I27/I17) | ... S28: =IF(S17=0,0,S27/S17)
A29: 広告費 | B29: =IF(1>=前提!$B$13,前提!$B$14,0) | C29: =IF(2>=前提!$B$13,前提!$B$14,0) | D29: =IF(3>=前提!$B$13,前提!$B$14,0) | E29: =IF(4>=前提!$B$13,前提!$B$14,0) | F29: =IF(5>=前提!$B$13,前提!$B$14,0) | G29: =IF(6>=前提!$B$13,前提!$B$14,0) | H29: =IF(7>=前提!$B$13,前提!$B$14,0) | I29: =IF(8>=前提!$B$13,前提!$B$14,0) | J29: =IF(9>=前提!$B$13,前提!$B$14,0) | K29: =IF(10>=前提!$B$13,前提!$B$14,0) | L29: =IF(11>=前提!$B$13,前提!$B$14,0) | M29: =IF(12>=前提!$B$13,前提!$B$14,0) | N29: =IF(13>=前提!$B$13,前提!$B$14,0) | O29: =IF(14>=前提!$B$13,前提!$B$14,0) | P29: =IF(15>=前提!$B$13,前提!$B$14,0) | Q29: =IF(16>=前提!$B$13,前提!$B$14,0) | R29: =IF(17>=前提!$B$13,前提!$B$14,0) | S29: =IF(18>=前提!$B$13,前提!$B$14,0)
A30: 固定費 | B30: =前提!$B$48 | C30: =前提!$B$48 | D30: =前提!$B$48 | E30: =前提!$B$48 | F30: =前提!$B$48 | G30: =前提!$B$48 | H30: =前提!$B$48 | I30: =前提!$B$48 | ... S30: =前提!$B$48
A31: 営業利益 | B31: =B27-B29-B30 | C31: =C27-C29-C30 | D31: =D27-D29-D30 | E31: =E27-E29-E30 | F31: =F27-F29-F30 | G31: =G27-G29-G30 | H31: =H27-H29-H30 | I31: =I27-I29-I30 | ... S31: =S27-S29-S30
A32: 累計営業利益 | B32: =B31 | C32: =B32+C31 | D32: =C32+D31 | E32: =D32+E31 | F32: =E32+F31 | G32: =F32+G31 | H32: =G32+H31 | I32: =H32+I31 | J32: =I32+J31 | ... S32: =R32+S31

Sheet CF
A1: 月次キャッシュフロー（M0=開業準備月〜M18）
B2: M0 | C2: M1 | D2: M2 | E2: M3 | F2: M4 | G2: M5 | H2: M6 | I2: M7 | J2: M8 | K2: M9 | L2: M10 | M2: M11 | N2: M12 | O2: M13 | P2: M14 | Q2: M15 | R2: M16 | S2: M17 | T2: M18
A3: 現金収入
A4: 現金収入（売上−決済手数料） | B4: 0 | C4: =PL!B17-PL!B21 | D4: =PL!C17-PL!C21 | E4: =PL!D17-PL!D21 | F4: =PL!E17-PL!E21 | G4: =PL!F17-PL!F21 | H4: =PL!G17-PL!G21 | I4: =PL!H17-PL!H21 | J4: =PL!I17-PL!I21 | ... T4: =PL!S17-PL!S21
A5: 在庫（原価ベース）
A6: 期首在庫 | B6: 0 | C6: =B9 | D6: =C9 | E6: =D9 | F6: =E9 | G6: =F9 | H6: =G9 | I6: =H9 | J6: =I9 | ... T6: =S9
A7: 仕入（発注＝同月前払い） | B7: =前提!$B$29 | C7: =MAX(0,PL!C19*前提!$B$35-(C6-PL!B19)) | D7: =MAX(0,PL!D19*前提!$B$35-(D6-PL!C19)) | E7: =MAX(0,PL!E19*前提!$B$35-(E6-PL!D19)) | F7: =MAX(0,PL!F19*前提!$B$35-(F6-PL!E19)) | G7: =MAX(0,PL!G19*前提!$B$35-(G6-PL!F19)) | H7: =MAX(0,PL!H19*前提!$B$35-(H6-PL!G19)) | I7: =MAX(0,PL!I19*前提!$B$35-(I6-PL!H19)) | J7: =MAX(0,PL!J19*前提!$B$35-(J6-PL!I19)) | ... S7: =MAX(0,PL!S19*前提!$B$35-(S6-PL!R19)) | T7: =MAX(0,PL!S19*1.05*前提!$B$35-(T6-PL!S19))
A8: 原価消費 | B8: 0 | C8: =PL!B19 | D8: =PL!C19 | E8: =PL!D19 | F8: =PL!E19 | G8: =PL!F19 | H8: =PL!G19 | I8: =PL!H19 | J8: =PL!I19 | ... T8: =PL!S19
A9: 期末在庫 | B9: =B6+B7-B8 | C9: =C6+C7-C8 | D9: =D6+D7-D8 | E9: =E6+E7-E8 | F9: =F6+F7-F8 | G9: =G6+G7-G8 | H9: =H6+H7-H8 | I9: =I6+I7-I8 | ... T9: =T6+T7-T8
A10: 現金支出
A11: 仕入支払 | B11: =B7 | C11: =C7 | D11: =D7 | E11: =E7 | F11: =F7 | G11: =G7 | H11: =H7 | I11: =I7 | ... T11: =T7
A12: 仕入送料 | B12: =IF(B7>0,前提!$B$23,0) | C12: =IF(C7>0,前提!$B$23,0) | D12: =IF(D7>0,前提!$B$23,0) | E12: =IF(E7>0,前提!$B$23,0) | F12: =IF(F7>0,前提!$B$23,0) | G12: =IF(G7>0,前提!$B$23,0) | H12: =IF(H7>0,前提!$B$23,0) | I12: =IF(I7>0,前提!$B$23,0) | ... T12: =IF(T7>0,前提!$B$23,0)
A13: 発送送料+破損（現金） | B13: 0 | C13: =PL!B22+PL!B24 | D13: =PL!C22+PL!C24 | E13: =PL!D22+PL!D24 | F13: =PL!E22+PL!E24 | G13: =PL!F22+PL!F24 | H13: =PL!G22+PL!G24 | I13: =PL!H22+PL!H24 | J13: =PL!I22+PL!I24 | ... T13: =PL!S22+PL!S24
A14: 資材消費 累計（参考） | B14: 0 | C14: =B14+PL!B23 | D14: =C14+PL!C23 | E14: =D14+PL!D23 | F14: =E14+PL!E23 | G14: =F14+PL!F23 | H14: =G14+PL!G23 | I14: =H14+PL!H23 | J14: =I14+PL!I23 | ... T14: =S14+PL!S23
A15: 資材購入（初期ロット消化後） | B15: 0 | C15: =MAX(0,C14-MAX(前提!$B$31,B14)) | D15: =MAX(0,D14-MAX(前提!$B$31,C14)) | E15: =MAX(0,E14-MAX(前提!$B$31,D14)) | F15: =MAX(0,F14-MAX(前提!$B$31,E14)) | G15: =MAX(0,G14-MAX(前提!$B$31,F14)) | H15: =MAX(0,H14-MAX(前提!$B$31,G14)) | I15: =MAX(0,I14-MAX(前提!$B$31,H14)) | J15: =MAX(0,J14-MAX(前提!$B$31,I14)) | ... T15: =MAX(0,T14-MAX(前提!$B$31,S14))
A16: 広告費 | B16: 0 | C16: =PL!B29 | D16: =PL!C29 | E16: =PL!D29 | F16: =PL!E29 | G16: =PL!F29 | H16: =PL!G29 | I16: =PL!H29 | J16: =PL!I29 | ... T16: =PL!S29
A17: 撮影ランニング（現金） | B17: 0 | C17: =前提!$B$27 | D17: =前提!$B$27 | E17: =前提!$B$27 | F17: =前提!$B$27 | G17: =前提!$B$27 | H17: =前提!$B$27 | I17: =前提!$B$27 | J17: =前提!$B$27 | ... T17: =前提!$B$27
A18: 年払い（Shopify+ドメイン） | B18: =前提!$B$33+前提!$B$34 | C18: 0 | D18: 0 | E18: 0 | F18: 0 | G18: 0 | H18: 0 | I18: 0 | J18: 0 | K18: 0 | L18: 0 | M18: 0 | N18: =前提!$B$33+前提!$B$34 | O18: 0 | P18: 0 | Q18: 0 | R18: 0 | S18: 0 | T18: 0
A19: 初期投資（撮影・資材・開業） | B19: =前提!$B$30+前提!$B$31+前提!$B$32 | C19: 0 | D19: 0 | E19: 0 | F19: 0 | G19: 0 | H19: 0 | I19: 0 | J19: 0 | K19: 0 | L19: 0 | M19: 0 | N19: 0 | O19: 0 | P19: 0 | Q19: 0 | R19: 0 | S19: 0 | T19: 0
A20: 現金支出 合計 | B20: =B11+B12+B13+B15+B16+B17+B18+B19 | C20: =C11+C12+C13+C15+C16+C17+C18+C19 | D20: =D11+D12+D13+D15+D16+D17+D18+D19 | E20: =E11+E12+E13+E15+E16+E17+E18+E19 | F20: =F11+F12+F13+F15+F16+F17+F18+F19 | G20: =G11+G12+G13+G15+G16+G17+G18+G19 | H20: =H11+H12+H13+H15+H16+H17+H18+H19 | I20: =I11+I12+I13+I15+I16+I17+I18+I19 | ... T20: =T11+T12+T13+T15+T16+T17+T18+T19
A21: キャッシュフロー
A22: 月次キャッシュフロー | B22: =B4-B20 | C22: =C4-C20 | D22: =D4-D20 | E22: =E4-E20 | F22: =F4-F20 | G22: =G4-G20 | H22: =H4-H20 | I22: =I4-I20 | ... T22: =T4-T20
A23: 累計キャッシュフロー | B23: =B22 | C23: =B23+C22 | D23: =C23+D22 | E23: =D23+E22 | F23: =E23+F22 | G23: =F23+G22 | H23: =G23+H22 | I23: =H23+I22 | J23: =I23+J22 | ... T23: =S23+T22
